<?xml version="1.0"?>
<robot xmlns:xacro="http://www.ros.org/wiki/xacro" name="mona">

    <xacro:property name="base_length"    value="1.25"/>
    <xacro:property name="base_width"     value="0.8"/>
    <xacro:property name="base_height"    value="0.3"/>
    <xacro:property name="base_mass"      value="150.0"/>
    
    <xacro:property name="wheel_radius"   value="0.1"/>
    <xacro:property name="wheel_width"    value="0.08"/>
    <xacro:property name="wheel_mass"     value="5.0"/>
    
    <xacro:property name="wheel_x_offset" value="0.40"/>
    <xacro:property name="wheel_y_offset" value="0.40"/>
    <xacro:property name="wheel_z_offset" value="-0.15"/>

    <link name="base_footprint"/>

    <joint name="base_joint" type="fixed">
        <parent link="base_footprint"/>
        <child link="base_link"/>
        <origin xyz="0 0 ${base_height/2.0 + 0.02}" rpy="0 0 0"/>
    </joint>

    <link name="base_link">
        <visual>
            <geometry>
                <box size="${base_length} ${base_width} ${base_height}"/>
            </geometry>
            <material name="orange">
                <color rgba="1.0 0.5 0.0 1.0"/>
            </material>
        </visual>

        <collision>
            <geometry>
                <box size="${base_length} ${base_width} ${base_height}"/>
            </geometry>
        </collision>

        <inertial>
            <mass value="${base_mass}"/>
            <inertia ixx="${(1/12) * base_mass * (base_width * base_width + base_height*base_height)}" ixy="0.0" ixz="0.0"
                     iyy="${(1/12) * base_mass * (base_length*base_length + base_height*base_height)}" iyz="0.0"
                     izz="${(1/12) * base_mass * (base_length*base_length + base_width*base_width)}"/>
        </inertial>
    </link>

    <gazebo reference="base_link">
        <material>Gazebo/Orange</material>
    </gazebo>

    <xacro:macro name="mecanum_wheel" params="name x y flip_visual">
        <link name="${name}_link">
            <visual>
                <origin xyz="0 0 0" rpy="${pi/2} 0 0"/>
                <geometry>
                    <cylinder radius="${wheel_radius}" length="${wheel_width}"/>
                </geometry>
                <material name="black">
                    <color rgba="0.1 0.1 0.1 1.0"/>
                </material>
            </visual>
            <collision>
                <origin xyz="0 0 0" rpy="${pi/2} 0 0"/>
                <geometry>
                    <cylinder radius="${wheel_radius}" length="${wheel_width}"/>
                </geometry>
            </collision>
            <inertial>
                <mass value="${wheel_mass}"/>
                <origin xyz="0 0 0" rpy="${pi/2} 0 0"/>
                <inertia ixx="${(1/12) * wheel_mass * (3*wheel_radius*wheel_radius + wheel_width*wheel_width)}" ixy="0" ixz="0"
                         iyy="${(1/12) * wheel_mass * (3*wheel_radius*wheel_radius + wheel_width*wheel_width)}" iyz="0"
                         izz="${(1/2) * wheel_mass * wheel_radius*wheel_radius}"/>
            </inertial>
        </link>

        <joint name="${name}_joint" type="continuous">
            <parent link="base_link"/>
            <child link="${name}_link"/>
            <origin xyz="${x} ${y} ${wheel_z_offset}" rpy="0 0 0"/>
            <axis xyz="0 1 0"/>
        </joint>

        <gazebo reference="${name}_link">
            <material>Gazebo/Black</material>
            <mu1>0.8</mu1> 
            <mu2>0.8</mu2>
        </gazebo>
    </xacro:macro>

    <xacro:mecanum_wheel name="front_left_wheel"  x="${wheel_x_offset}"  y="${wheel_y_offset}"  flip_visual="1"/>
    <xacro:mecanum_wheel name="front_right_wheel" x="${wheel_x_offset}"  y="-${wheel_y_offset}" flip_visual="0"/>
    <xacro:mecanum_wheel name="rear_left_wheel"   x="-${wheel_x_offset}" y="${wheel_y_offset}"  flip_visual="1"/>
    <xacro:mecanum_wheel name="rear_right_wheel"  x="-${wheel_x_offset}" y="-${wheel_y_offset}" flip_visual="0"/>

    <gazebo>
        <plugin name="object_controller" filename="libgazebo_ros_planar_move.so">
            <ros>
                <argument>odom:=odom/unfiltered</argument>
            </ros>
            <command_topic>cmd_vel</command_topic>
            <odometry_topic>odom</odometry_topic>
            <odometry_frame>odom</odometry_frame>
            <odometry_rate>20.0</odometry_rate>
            <robot_base_frame>base_footprint</robot_base_frame>
            <publish_odom>true</publish_odom>
            <publish_odom_tf>true</publish_odom_tf>
        </plugin>
    </gazebo>

</robot>